Workbook
Name a: #REF!
Name a: #REF!
Name a: #REF!
Name a: #REF!
Name Table9: #REF!
Name Table9: #REF!
Name Table9: #REF!
Name Table9: #REF!
Name Table9: #REF!
Name Table93: 'Engineering Page'!$H$2:$I$6

Sheet Note
A1: Rule | B1: Note
A2: 1 | B2: Please DO NOT CHANGE any word in column colour Black & Yellow
A3: 2 | B3: Please do not combine different Connection Tag in a same sheet.
A4: 3 | B4: Please Do Not Remove The Warning & Error Sheet (It need to be located on 13 and 14 sheet
B5: The tab sheet with the DARK BLUE colour is a page with FIXED ADDRESS. Please do inform, or make a note if there is a address changes in the page
A6: 4 | B6: Please fill in the bracket color with : (Refer Below)
B7: For New Tag Address, New Feature, or New Pages (Orange,Accent 2)
B8: Change Existing Address (Light Blue)
B9: Temporary No Need (Red)
B10: Remove/Did Not Use In HMI (remove or just fill the column with black colour)
A11: 5 | B11: Make sure the tab of Warning List and Error List is on 13th and 14th tab
A13: *Do not modify this changelog when creating for project
A14: HMI List Template Changelog
A15: Version | B15: Description | C15: Date | D15: Author

Sheet Changelog
A1: Project Name:
A2: *Always remember to update this whenever there is any changes
A3: HMI List Changelog
A4: No | C4: Description | D4: Author | E4: Source Code Version
B5: Date | E5: HMI | F5: PLC
A6: 1 | C6: Update Error List: Added Error #31 Update data type for: - Main page: Refer to cells highlighted in orange - Engineering page: Axis position array(EM20000 - EM20005), HMI_Key-In_PosValue(EM4030 - EM4035) - Added devices on Output Page: MR108, MR113, MR114
A7: 2 | C7: Updated Output Page device list
A8: 3 | C8: Updates: - Updated Cycle Time device list - Removed R40002, R40003 from Input Page - Removed MR403 from Output Page - Updated motor page device list
A9: 4 | C9: Updates: - Main Page: Start, Stop, Reset address - Error List: Added Error 11 & 23 - Prompt Window: Added Clamp Side Column Prompt window for top right corner
A10: 5 | C10: Updates: - Main Page: Added module statuses - Error List: Added Error 75, 93, 98, 100, 134, 138, 141, 142 Already modified on HMI: - OEE: Added string length for Lot OEE - CAMLine: Changed device address for BOOL type
A11: 6 | C11: Updated address on Input Page
A12: 7 | C12: Added Error 34 in Error List, Added new window prompt
A13: 8 | C13: Prompt Window: Updated Prompt Window tags and namings Input Page: Removed R10603 Output Page: Removed MR300
A14: 9 | C14: Updates: - Lot Entry: Moved shell colour selection to from Main Page to Lot Entry Page, updated tag name (black shell) - Input Page & Output Page: Refer to IO List for new naming - Setting: Removed Monitor tags Updated on HMI: - Main Page: Added screw quantity tags
A15: 10 | C15: Updates: - Added side column type selection to Lot Entry Page
A16: 11 | C16: Updates: - Added 2 new HMI prompt on Prompt Window Tab
A17: 12 | B17: 45881 | C17: Updates: - Added 2 new HMI prompt on Prompt Window Tab (Remove Side Handle Jig & Remove Side Column)

Sheet Main Page
A1: Main Page
B2: PLC IP: | C2: 192.168.0.10
B3: NAME FOR PC: | C3: HMI PC
B4: S7 Connection | C4: Connection1
F5: *Machine Status*
B6: Tag Name | C6: Data Type | D6: Address | F6: Description | G6: Status No. | H6: Colour | I6: Blinking
B7: Machine_Status | C7: Int | D7: EM103 | F7: Running | G7: 1 | H7: Green | I7: No
B8: Machine Speed | C8: Int | D8: %DB452.DBW10 | F8: Idle | G8: 2 | H8: Blue | I8: No
B9: Production UPH | C9: DInt | D9: EM1254 | F9: Not Init Done | G9: 3 | H9: Blue | I9: No
B10: Yield | C10: DInt | D10: EM1260 | F10: Init | G10: 4 | H10: Blue | I10: No
B11: Machine Mode | C11: Int | D11: EM104 | F11: Stop | G11: 5 | H11: Red | I11: No
B12: Machine_Name | C12: String[40] | D12: EM770 | F12: Error | G12: 6 | H12: Red | I12: Yes
B13: Project_No | C13: String[20] | D13: EM950 | F13: Warning | G13: 7 | H13: Yellow | I13: Yes
B14: Total Pass Foup | C14: Dint | D14: EM1759 | F14: EMG | G14: 8 | H14: Red | I14: No
B15: Total Fail Foup | C15: Dint | D15: EM1761
B16: Lot_Quantity | C16: Dint | D16: EM1561 | F16: *Machine Mode *
B17: Assembly Foup | C17: Dint | D17: EM1634 | F17: Description | G17: Status No. | H17: Colour
B18: Loaded Shell | C18: Bool | D18: R20000 | F18: Production | G18: 0 | H18: Green
B19: Loaded Side Column | C19: Bool | D19: EM5.12 | F19: Engineering Mode | G19: 1 | H19: Blue
B20: Loaded Shim & O-Ring | C20: Bool | D20: EM21.13 | F20: Dry Run | G20: 7 | H20: Green
B23: Tag Name | C23: Data Type | D23: Address
B24: HMI_Start | C24: Bool | D24: MR000
B25: HMI_Stop | C25: Bool | D25: MR001
B26: HMI_Reset | C26: Bool | D26: MR002
A30: Error/Warning | B30: Tag Name | C30: Data Type | D30: Address
B31: Error_String | C31: String[256] | D31: EM201
B32: Tmp_Error_String | C32: String[256] | D32: EM340
B33: Warning_String | C33: String[256] | D33: EM480
B34: Tmp_Warning_String | C34: String[256] | D34: EM630
B35: No_Error | C35: Bool | D35: %DB450.DBX0.5
A38: Program Version | B38: Tag Name | C38: Data Type | D38: Address
B39: PLC_Program_Version | C39: String[26] | D39: EM910
B40: HMI_Program_Version | C40: String[26] | D40: EM930
B41: Robot_Program_Version | C41: String[26]
B42: Vision_Program_Version | C42: String[26] | D42: %DB450.DBX1082.0
A44: Machine Mode
B45: Tag Name | C45: Data Type | D45: Address
B46: Engineering Mode Bit | C46: Bool | D46: MR1000
A48: IO Page
B49: Tag Name | C49: Data Type | D49: Address
...

Sheet DryRun Page
A1: Dry Run
B2: PLC IP: | C2: 192.168.0.10
B3: NAME FOR PC: | C3: ='Main Page'!C3 -> HMI PC
B4: S7 Connection | C4: ='Main Page'!C4 -> Connection1
B7: Dry Run Name | C7: Name | D7: Data Type | E7: Address
B8: Dry Run1 | C8: EnableDryRun | D8: Bool | E8: MR4000
C9: DryRunName | D9: String[20] | E9: DM3000
C10: DryRunStart | D10: Bool | E10: MR4001
C11: DryRunReset | D11: Bool | E11: MR4002
C12: DryRun_SoftJamCount | D12: Int | E12: DM3012
C13: DryRun_HardJamCount | D13: Int | E13: DM3013
C14: DryRun_RunTime | D14: DInt | E14: DM3014
C15: DryRun_IdlingTime | D15: DInt | E15: DM3016
C16: DryRun_DownTime | D16: DInt | E16: DM3018
B17: Dry Run2 | C17: EnableDryRun | D17: Bool | E17: MR4008
C18: DryRunName | D18: String[20] | E18: DM3020
C19: DryRunStart | D19: Bool | E19: MR4009
C20: DryRunReset | D20: Bool | E20: MR4010
C21: DryRun_SoftJamCount | D21: Int | E21: DM3032
C22: DryRun_HardJamCount | D22: Int | E22: DM3033
C23: DryRun_RunTime | D23: DInt | E23: DM3034
C24: DryRun_IdlingTime | D24: DInt | E24: DM3036
C25: DryRun_DownTime | D25: DInt | E25: DM3038
B26: Dry Run3 | C26: EnableDryRun | D26: Bool | E26: MR4100
C27: DryRunName | D27: String[20] | E27: DM3040
C28: DryRunStart | D28: Bool | E28: MR4101
C29: DryRunReset | D29: Bool | E29: MR4102
C30: DryRun_SoftJamCount | D30: Int | E30: DM3052
C31: DryRun_HardJamCount | D31: Int | E31: DM3053
C32: DryRun_RunTime | D32: DInt | E32: DM3054
C33: DryRun_IdlingTime | D33: DInt | E33: DM3056
C34: DryRun_DownTime | D34: DInt | E34: DM3058
B35: Dry Run4 | C35: EnableDryRun | D35: Bool | E35: MR4108
C36: DryRunName | D36: String[20] | E36: DM3060
C37: DryRunStart | D37: Bool | E37: MR4109
C38: DryRunReset | D38: Bool | E38: MR4110
C39: DryRun_SoftJamCount | D39: Int | E39: DM3072
C40: DryRun_HardJamCount | D40: Int | E40: DM3073
C41: DryRun_RunTime | D41: DInt | E41: DM3074
C42: DryRun_IdlingTime | D42: DInt | E42: DM3076
...

Sheet OEE
A1: OEE
B2: PLC IP: | C2: 192.168.0.10
B3: NAME FOR PC: | C3: ='Main Page'!C3 -> HMI PC
B4: S7 Connection | C4: ='Main Page'!C4 -> Connection1
A7: Lot OEE
B8: Tag Name | C8: Data Type | D8: Address
B9: Start Date Time | C9: String[21] | D9: EM1782
B10: New Lot ID String | C10: String[50] | D10: EM1501
B11: Operator_ID | C11: String[10] | D11: EM1553
B12: Total Quantity Out | C12: DInt | D12: EM1763
B13: Total Quantity In | C13: DInt | D13: EM1767
B14: Total Passed | C14: DInt | D14: EM1759
B15: Total Failed | C15: DInt | D15: EM1761
B16: System Up Time | C16: DInt | D16: EM1736
B17: Operation Time | C17: DInt | D17: EM1738
B18: Down Time | C18: DInt | D18: EM1740
B19: Idle Time | C19: DInt | D19: EM1742
... B24: Total_Yield | C24: DInt | D24: EM1765
A27: Shift OEE
B28: Tag Name | C28: Data Type | D28: Address
B29: Start Date Time | C29: String[22] | D29: EM1076
B30: Machine Name | C30: String[40] | D30: EM770
B31: Total Quantity In | C31: DInt | D31: EM1058
B32: Total Quantity Out | C32: DInt | D32: EM1054
B33: Total Passed | C33: DInt | D33: EM1050
B34: Total Failed | C34: DInt | D34: EM1052
B35: System Up Time | C35: DInt | D35: EM1030
B36: Operation Time | C36: DInt | D36: EM1032
B37: Down Time | C37: DInt | D37: EM1034
B38: Idle Time | C38: DInt | D38: EM1036
B39: Soft Jam | C39: Int | D39: EM1060
... B43: Total_Yield | C43: DInt | D43: EM1056
A45: Hourly UPH
B46: Tag Name | C46: Data Type | D46: Address
B47: UPH_Hourly_0 | C47: DInt | D47: EM1200
B48: UPH_Hourly_1 | C48: DInt | D48: EM1202
B49: UPH_Hourly_2 | C49: DInt | D49: EM1204
B50: UPH_Hourly_3 | C50: DInt | D50: EM1206
B51: UPH_Hourly_4 | C51: DInt | D51: EM1208
B52: UPH_Hourly_5 | C52: DInt | D52: EM1210
...

Sheet Input Page
A1: Input
B2: PLC IP: | C2: 192.168.0.10
B3: NAME FOR PC: | C3: ='Main Page'!C3 -> HMI PC
B4: S7 Connection | C4: ='Main Page'!C4 -> Connection1
B7: Name | C7: Data Type | D7: Address
B8: Touch Button Signal | C8: Bool | D8: R10200
B9: Start Button | C9: Bool | D9: R10201
B10: Stop Button | C10: Bool | D10: R10202
B11: Reset Button | C11: Bool | D11: R10203
B12: E-Stop Button 1 | C12: Bool | D12: R10204
B13: E-Stop Reset Button | C13: Bool | D13: R10205
B14: Safety Relay Signal | C14: Bool | D14: R10206
B15: Incoming Air Pressure Switch | C15: Bool | D15: R10207
B16: Curtain Sensor Signal | C16: Bool | D16: R10208
B17: E-Stop Button 2 | C17: Bool | D17: R10209
B18: Safety Door Lock Signal | C18: Bool | D18: R10210
... B63: FIAM Tighten Error | C63: Bool | D63: R20403
A64: End | B64: FIAM System Faulty | C64: Bool | D64: R20404

Sheet Output Page
A1: Output
B2: PLC IP: | C2: 192.168.0.10
B3: NAME FOR PC: | C3: ='Main Page'!C3 -> HMI PC
B4: S7 Connection | C4: ='Main Page'!C4 -> Connection1
B7: Name | C7: Data Type | D7: Address
B8: Start Button Indicator | C8: Bool | D8: MR100
B9: Stop Button Indicator | C9: Bool | D9: MR101
B10: Reset Button Indicator | C10: Bool | D10: MR102
B11: EMO Reset Button Indicator | C11: Bool | D11: MR103
B12: Tower Light Red | C12: Bool | D12: MR104
B13: Tower Light Orange | C13: Bool | D13: MR105
B14: Tower Light Green | C14: Bool | D14: MR106
B15: Tower Light Buzzer | C15: Bool | D15: MR107
B16: Cobot Init Signal | C16: Bool | D16: MR108
B17: DC Power Trigger On | C17: Bool | D17: MR109
B18: Soft Start Valve | C18: Bool | D18: MR110
... B56: FIAM Bit Advancement | C56: Bool | D56: MR504
A60: End

Sheet Lot Entry
A1: Lot Entry
B2: PLC IP: | C2: 192.168.0.10
B3: NAME FOR PC: | C3: ='Main Page'!C3 -> HMI PC
B4: S7 Connection | C4: ='Main Page'!C4 -> Connection1
A8: Main Line | B8: Tag Name | C8: Address | D8: Data Type | E8: Retain
B9: Work Order Started | C9: MR49500 | D9: Bool | E9: Yes
B10: Work Order ID | C10: EM1501 | D10: String[50] | E10: Yes
B11: Set Work Order Info Button | C11: MR49501 | D11: Bool | E11: Yes
B12: End Work Order Button | C12: MR49502 | D12: Bool | E12: Yes
B13: Operator ID | C13: EM1553 | D13: String[10] | E13: Yes
B14: Recipe | C14: EM1559 | D14: Dint | E14: Yes
B15: Lot Quantity | C15: EM1561 | D15: Dint | E15: Yes
B16: OK To End Work Order | C16: MR49503 | D16: Bool | E16: Yes
B17: Current Quantity | C17: EM1634 | D17: Dint | E17: Yes
A21: Machine Mode | B21: Tag Name | C21: Data Type | D21: Address
B22: Production Mode | C22: Bool
B23: Dry Run Mode | C23: Bool | D23: MR1001
B24: Engineering Mode | C24: Bool | D24: MR1000
A26: Shell Colour | B26: Tag Name | C26: Data Type | D26: Address
B27: Black | C27: Bool | D27: MR4500
B28: Transparent | C28: Bool | D28: MR4501
B29: Amber | C29: Bool | D29: MR4502
B30: Green | C30: Bool | D30: MR4503
B31: Red | C31: Bool | D31: MR4504
B32: Blue | C32: Bool | D32: MR4511
A34: Side column Type
B35: Tag Name | C35: Data Type | D35: Address
B36: TSO column | C36: Bool | D36: MR4515
A38: End

Sheet Engineering Page
A1: EM
B2: PLC IP: | C2: 192.168.0.10 | H2: Position
B3: NAME FOR PC: | C3: ='Main Page'!C3 -> HMI PC | I3: Position Tag Name | J3: Data Type | K3: Offset | L3: Axis1
B4: S7 Connection | C4: ='Main Page'!C4 -> Connection1 | I4: Axis_Positions[0] | J4: DInt | L4: EM20000
I5: Axis_Positions[1] | J5: DInt | L5: EM20002
B6: Tag Name | C6: Address | D6: Data Type | E6: Toggle | I6: Axis_Positions[2] | J6: DInt | L6: EM20004
B7: Engineering Mode Bit | C7: MR1000 | D7: Bool | E7: Yes
H10: Toggle
I11: Motor Tag Name | J11: Data Type | K11: Offset | L11: Axis1
I12: HMI_Save_Current_Pos[0] | J12: Bool | L12: MR2100
I13: HMI_Save_Current_Pos[1] | J13: Bool | L13: MR2101
I14: HMI_Save_Current_Pos[2] | J14: Bool | L14: MR2102
I15: HMI_Save_Key-In_Pos[0] | J15: Bool | L15: MR2200
I16: HMI_Save_Key-In_Pos[1] | J16: Bool | L16: MR2201
I17: HMI_Save_Key-In_Pos[2] | J17: Bool | L17: MR2202
I18: HMI_Key-In_PosValue[0] | J18: DInt | L18: EM4030
I19: HMI_Key-In_PosValue[1] | J19: DInt | L19: EM4032
I20: HMI_Key-In_PosValue[2] | J20: DInt | L20: EM4034
I21: HMI_ManualGo[0] | J21: Bool | L21: MR2300
I22: HMI_ManualGo[1] | J22: Bool | L22: MR2301
I23: HMI_ManualGo[2] | J23: Bool | L23: MR2302
... I26: Axis_Position_Reached[2] | J26: Bool | L26: MR2402
A110: End

Sheet Cycle Time
A1: Cycle Time
B2: PLC IP: | C2: ='Main Page'!C2 -> 192.168.0.10
B3: NAME FOR PC: | C3: ='Main Page'!C3 -> HMI PC
B4: S7 Connection | C4: ='Main Page'!C4 -> Connection1
A5: Module#1
B6: Name | C6: Offset | D6: Data Type | E6: Address
B7: Cycle Time_1_Enable Cycle Time | C7: 0 | D7: Bool | E7: MR3500
B8: Cycle Time_1_Cycle Time Name | C8: 2 | D8: String[20] | E8: DM3548
B9: CycleTime_1_HMI Capture | C9: 24 | D9: Bool | E9: MR3501
B10: CycleTime_1_Cycle Time Timer | C10: 26 | D10: Real | E10: DM3500
B11: CycleTime_1_Cycle Time Last Timer | C11: 30 | D11: Real | E11: DM3502
B12: CycleTime_1_Cycle Time Start | C12: 34 | D12: Bool | E12: MR3502
B13: CycleTime_1_Arr_Last Timer_1[0] | C13: 36 | D13: Real | E13: DM3504
B14: CycleTime_1_Arr_Last Timer_1[1] | C14: 40 | D14: Real | E14: DM3506
B15: CycleTime_1_Arr_Last Timer_1[2] | C15: 44 | D15: Real | E15: DM3508
B16: CycleTime_1_Arr_Last Timer_1[3] | C16: 48 | D16: Real | E16: DM3510
B17: CycleTime_1_Arr_Last Timer_1[4] | C17: 52 | D17: Real | E17: DM3512
B18: CycleTime_1_Arr_Last Timer_1[5] | C18: 56 | D18: Real | E18: DM3514
... B23: CycleTime_1_Arr_Last Timer_1[10] | C23: 76 | D23: Real | E23: DM3524
A24: Module#2
B25: Name | C25: Offset | D25: Data Type | E25: Address
B26: Cycle Time_2_Enable Cycle Time | C26: 124 | D26: Bool | E26: MR3504
B27: Cycle Time_2_Cycle Time Name | C27: 126 | D27: String[20] | E27: DM3660
B28: Cycle Time_2_HMI Capture | C28: 148 | D28: Bool | E28: MR3505
B29: Cycle Time_2_Cycle Time Timer | C29: 150 | D29: Real | E29: DM3600
B30: Cycle Time_2_Cycle Time Last Timer | C30: 154 | D30: Real | E30: DM3602
B31: Cycle Time_2_Cycle Time Start | C31: 158 | D31: Bool | E31: MR3506
B32: Cycle Time_2_Arr_Last Timer_1[0] | C32: 160 | D32: Real | E32: DM3604
B33: Cycle Time_2_Arr_Last Timer_1[1] | C33: 164 | D33: Real | E33: DM3606
B34: Cycle Time_2_Arr_Last Timer_1[2] | C34: 168 | D34: Real | E34: DM3608
B35: Cycle Time_2_Arr_Last Timer_1[3] | C35: 172 | D35: Real | E35: DM3610
B36: Cycle Time_2_Arr_Last Timer_1[4] | C36: 176 | D36: Real | E36: DM3612
B37: Cycle Time_2_Arr_Last Timer_1[5] | C37: 180 | D37: Real | E37: DM3614
... B42: Cycle Time_2_Arr_Last Timer_1[10] | C42: 200 | D42: Real | E42: DM3624
A43: Module#3
B44: Name | C44: Offset | D44: Data Type | E44: Address
B45: Cycle Time_3_Enable Cycle Time | C45: 248 | D45: Bool | E45: MR3508
B46: Cycle Time_3_Cycle Time Name | C46: 250 | D46: String[20] | E46: DM3760
B47: Cycle Time_3_HMI Capture | C47: 272 | D47: Bool | E47: MR3509
B48: Cycle Time_3_Cycle Time Timer | C48: 274 | D48: Real | E48: DM3700
...

Sheet Setting
A1: Setting
B2: PLC IP: | C2: 192.168.0.10
B3: NAME FOR PC: | C3: ='Main Page'!C3 -> HMI PC
B4: S7 Connection | C4: ='Main Page'!C4 -> Connection1
A6: Bypass
B7: Tag Name(Bypass Bit) | C7: Address | D7: Data Type | E7: Retain | F7: Toggle
B8: Bypass Door Switch | C8: MR1200 | D8: Bool | E8: Yes | F8: Yes
B9: Bypass E-Stop | C9: MR1201 | D9: Bool | E9: Yes | F9: Yes
B10: Bypass Safety Relay | C10: MR1202 | D10: Bool | E10: Yes | F10: Yes
B11: Bypass Pressure Switch | C11: MR1203 | D11: Bool | E11: Yes | F11: Yes
B12: Bypass Buzzer | C12: MR1204 | D12: Bool | E12: Yes | F12: Yes
B13: Bypass Shell Load Module Sensor | C13: MR1205 | D13: Bool | E13: Yes | F13: Yes
B14: Bypass Side Column Module Sensor | C14: MR1206 | D14: Bool | E14: Yes | F14: Yes
B15: Bypass Curtain Sensor | C15: MR1207 | D15: Bool | E15: Yes | F15: Yes
B16: Bypass Screw Driver Sequence | C16: MR1208 | D16: Bool | E16: Yes | F16: Yes
B17: Bypass CAMLINE | C17: MR1209 | D17: Bool | E17: Yes | F17: Yes
B18: Bypass Soft Start Valve | C18: MR1210 | D18: Bool | E18: Yes | F18: Yes
A21: General
B22: Tag Name | C22: Address | D22: Data Type | E22: Retain | F22: Toggle
B23: Machine Speed | C23: %DB452.DBW10 | D23: Int | E23: Yes | F23: NumericUpDown
A27: Monitor
B28: Tag Name | C28: Address | D28: Data Type | E28: Retain | F28: R/W
B29: O-Ring Loaded | C29: EM13.14 | D29: Bool | E29: Yes | F29: Read
B30: Shim Loaded | C30: EM13.15 | D30: Bool | E30: Yes | F30: Read
A127: End

Sheet Warning List
A1: Warning
B2: PLC IP: | C2: 192.168.0.10
B3: NAME FOR PC: | C3: ='Main Page'!C3 -> HMI PC
B4: S7 Connection | C4: ='Main Page'!C4 -> Connection1
B6: MachineStatus.WarningCode(UINT) | C6: Module | D6: Warning | E6: Action | F6: 警报 | G6: 建议
B7: 1 | C7: General | D7: Door Switch Bypassed
B8: 2 | C8: General | D8: Curtain Sensor Blocked | E8: If unintended, please check signal (I 3.2) and remove obstacle from Curtain Sensor. Robot speed reduced until blockage removed
B9: 3
B10: 4
B11: 5
B12: 6
B13: 7
B14: 8
B15: 9
B16: 10
B17: 11 | C17: General | D17: No Lot Created | E17: Please create new lot first before starting machine
B18: 12 | C18: General | D18: Operator Timeout | E18: Press Reset button and follow prompt to continue machine operation
B19: 13
B20: 14
B21: 15
B22: 16
B23: 17
B24: 18
B25: 19
B26: 20
B27: 21
B28: 22
B29: 23
B30: 24
... B1006: 1000
A1007: End

Sheet Error List
A1: Error
B2: PLC IP: | C2: 192.168.0.10
B3: NAME FOR PC: | C3: ='Main Page'!C3 -> HMI PC
B4: S7 Connection | C4: ='Main Page'!C4 -> Connection1
B6: MachineStatus.ErrorCode(UINT) | C6: Module | D6: Warning | E6: Action | F6: 警报 | G6: 建议
B7: 1 | C7: General | D7: Safety Relay Not On | E7: Please make sure all EMO buttons are released and press the blue Reset Button at the back of the machine followed by the orange Reset and Start Button.
B8: 2 | C8: General | D8: Low Incoming Air Pressure | E8: Please check the incoming air pressure (I1.7). Press Reset and Start Button to continue when ready.
B9: 3 | C9: General | D9: Estop Button 1 Pressed | E9: Release Estop Button 1 (I1.4) at machine front. Press the blue Reset Button at the back of the machine, followed by the orange Reset button and Start button.
B10: 4 | C10: General | D10: Estop Button 2 Pressed | E10: Release Estop Button 2 (I1.9) at machine front. Press the blue Reset Button at the back of the machine, followed by the orange Reset button and Start button.
B11: 5
B12: 6 | C12: General | D12: Unable to Start Program in Engineering Mode | E12: Please exit Engineering Mode by selecting the Engineering Mode button on the right of the screen and press Reset and Start Button
B13: 7
B14: 8 | C14: General | D14: Door Opened | E14: Please ensure the maintenance doors are closed properly. If doors are closed, check Door Switch signals (I1.10, I1.13-I1.15)
B15: 9
B16: 10
B17: 11 | C17: General | D17: Module Lost Communication | E17: Please check the Ethernet connection status on URRobot, IO cards and Vision units. Press Reset and Start Button when ready
B18: 12
B19: 13
B20: 14
B21: 15
B22: 16
B23: 17
B24: 18
B25: 19
B26: 20
B27: 21 | C27: Robot | D27: Robot Error | E27: Please check Robot status with Teach Pendant and press Reset and Start to continue
B28: 22 | C28: Robot | D28: Robot System Error | E28: Please check Robot Controller status and press Reset and Start to continue
B29: 23 | C29: Robot | D29: Robot Fail To Power On | E29: Please check Robot Controller status and press Reset and Start to continue
B30: 24
B31: 25 | C31: Robot | D31: Robot Estop On | E31: Please check Robot Controller status and press Reset and Start to continue
B32: 26 | C32: Robot | D32: Robot Fail To Start | E32: Please check Robot status with Teach Pendant and press Reset and Start to continue
B33: 27 | C33: Robot | D33: Robot Fail To Stop | E33: Please check Robot status with Teach Pendant and press Reset and Start to continue
B34: 28 | C34: Robot | D34: Robot Fail To Reset | E34: Please check Robot status with Teach Pendant and press Reset and Start to continue
B35: 29 | C35: Robot | D35: Robot Fail To Pause | E35: Please check Robot status with Teach Pendant and press Reset and Start to continue
B36: 30 | C36: Robot | D36: Robot Fail To Init | E36: Please check that the robot is in Remote Control mode and press Reset and Start to continue
B37: 31 | C37: Robot | D37: Robot Fail To Home | E37: Please check Robot status with Teach Pendant and press Reset and Start to continue
B38: 32
B39: 33 | C39: Robot | D39: Robot Movement Error | E39: Please check Robot status with Teach Pendant and press Reset and Start to continue
B40: 34 | C40: Robot | D40: Robot Protective Stopped | E40: Please check the robot condition, enable robot with teach pendant, press Reset and Start to continue
B41: 35
...

Sheet Change Password
A1: Access Right
B2: PLC IP: | C2: ='Main Page'!C2 -> 192.168.0.10
B3: NAME FOR PC: | C3: ='Main Page'!C3 -> HMI PC | E3: !HMI Internal
B4: S7 Connection | C4: ='Main Page'!C4 -> Connection1
A8: Change Password
B9: Tag Name | C9: Address | D9: Data Type | E9: Retain | F9: Toggle
B10: User ID | D10: String | E10: Yes | F10: Write
B11: Old Password | D11: String | E11: Yes | F11: Write
B12: New Password | D12: String | E12: Yes | F12: Write
B13: Confirm Password | D13: String | E13: Yes | F13: Write
B14: HMI_Change_Password | D14: Bool | E14: No | F14: On
A17: Add User
B18: Tag Name | C18: Address | D18: Data Type | E18: Retain | F18: Toggle
B19: HMI_Select_User_Level
B20: User ID | D20: String | E20: Yes | F20: Write
B21: HMI_Add_New_User | D21: Bool | E21: No | F21: On
A24: Delete ID
B25: Tag Name | C25: Address | D25: Data Type | E25: Retain | F25: Toggle
B26: HMI_Delete_ID | D26: Bool | E26: No | F26: On
A51: End

Sheet Access Right
A1: Access Right
B2: PLC IP: | C2: 192.168.0.10
B3: NAME FOR PC: | C3: ='Main Page'!C3 -> HMI PC
B4: S7 Connection | C4: ='Main Page'!C4 -> Connection1
B8: Types of Access | C8: Operator | D8: Penta | E8: Admin
B9: Main Page | C9: Enable | D9: Enable | E9: Enable
B10: Lot Entry | C10: Enable | D10: Enable | E10: Enable
B11: OEE | C11: Enable | D11: Enable | E11: Enable
B12: Engineering Page | C12: Disable | D12: Enable | E12: Enable
B13: Setting | C13: Disable | D13: Enable | E13: Enable
B14: IO Location | C14: Disable | D14: Enable | E14: Enable
B15: IO List | C15: Disable | D15: Enable | E15: Enable
B16: Motor | C16: Disable | D16: Enable | E16: Enable
B17: Configuration | C17: Disable | D17: Disable | E17: Enable
B18: GRR | C18: Disable | D18: Enable | E18: Enable
B19: Dry Run | C19: Disable | D19: Enable | E19: Enable
... B21: Recipe | C21: Disable | D21: Enable | E21: Enable
B23: Username | C23: Password | D23: Level
B24: penta | C24: #penta123 | D24: pentamaster
B25: entegris | C25: 123321 | D25: technician
A51: End

Sheet Prompt Window
A1: Colours are just to indicate type of prompt windows, don't need to follow colour code. Feel free to change the layout and position of the prompt window to follow previous Entegris projects
B2: Load A300 Shell, Handles
C4: Tag Name | D4: Address | E4: Data Type | F4: R/W
C5: HMI_Prompt_Load_Shell_Handle | D5: MR1500 | E5: Bool | F5: Read
C6: Info Message | D6: EM3100 | E6: String[100] | F6: Read
B8: Load Conveyor Plate
C10: Tag Name | D10: Address | E10: Data Type | F10: R/W
C11: HMI_Prompt_Load_Convyr_Plate | D11: MR1501 | E11: Bool | F11: Read
C12: Info Message | D12: EM3160 | E12: String[100] | F12: Read
B14: Load Side Column
C16: Tag Name | D16: Address | E16: Data Type | F16: R/W
C17: HMI_Prompt_Load_Side_Col | D17: MR1502 | E17: Bool | F17: Read
C18: Info Message | D18: EM3220 | E18: String[100] | F18: Read
B20: Clamp Side Column
C22: Tag Name | D22: Address | E22: Data Type | F22: R/W
C23: HMI_Prompt_Clamp_Side_Col | D23: MR1511 | E23: Bool | F23: Read
C24: Start | D24: MR1600 | E24: Bool | F24: Write
C25: Info Message | D25: EM3340 | E25: String[100] | F25: Read
B27: Start Side Column Sequence
C29: Tag Name | D29: Address | E29: Data Type | F29: R/W
C30: HMI_Prompt_Start_Side_Col_Seq | D30: MR1504 | E30: Bool | F30: Read
C31: Start | D31: MR1606 | E31: Bool | F31: Write
C32: Info Message | D32: EM3700 | E32: String[100] | F32: Read
B34: Shim and O-Ring Check Failed
C36: Tag Name | D36: Address | E36: Data Type | F36: R/W
C37: HMI_Prompt_Shim_Oring_Failed | D37: MR1505 | E37: Bool | F37: Read
C38: Retry | D38: MR1602 | E38: Bool | F38: Write
C39: Remove | D39: MR1601 | E39: Bool | F39: Write
C40: Info Message | D40: EM3400 | E40: String[254] | F40: Read
B42: Screw Failed
C44: Tag Name | D44: Address | E44: Data Type | F44: R/W
C45: HMI_Prompt_Screw_Failed | D45: MR1503 | E45: Bool | F45: Read
C46: Retry | D46: MR1603 | E46: Bool | F46: Write
C47: Remove | D47: MR1601 | E47: Bool | F47: Write
C48: Info Message | D48: EM3280 | E48: String[254] | F48: Read
B50: Unload Shell
C52: Tag Name | D52: Address | E52: Data Type | F52: R/W
C53: HMI_Prompt_Unload_Shell | D53: MR1506 | E53: Bool | F53: Read
C54: Info Message | D54: EM3460 | E54: String[100] | F54: Read
B56: Screw Feed Failed
...

Sheet Recipe
B2: Name | C2: Address | D2: DataType | E2: Remark | G2: Features | H2: penta access | I2: admin access | J2: Remark | L2: Item | M2: A300
B3: Total Contact Position | C3: %MW12 | D3: Int | G3: New | H3: Enable | I3: Enable | L3: Recipe Number | M3: 1
B4: Total Round Bush Position | C4: %MW32 | D4: Int | G4: Save | H4: Enable | I4: Enable
B5: Total Side Vision Corner Position | C5: %MW20 | D5: Int | G5: Copy | H5: Disable | I5: Enable
B6: Total Side Vision Latch Position | C6: %MW16 | D6: Int | G6: Paste | H6: Disable | I6: Enable
B7: Total Side Vision Number Code Position | C7: %MW28 | D7: Int | G7: Delete | H7: Enable | I7: Enable
B8: Total Side Vision Wafer Retainer Nodes Position | C8: %MW24 | D8: Int | G8: Recipe Name | H8: Read and write | I8: Read and write
B9: Flatness Check Preset Value | C9: %MD44 | D9: Real | E9: 3 Decimal Places | G9: Recipe Number | H9: Read only | I9: Read only
B10: Flatness Check Upper Limit | C10: %MD48 | D10: Real | E10: 3 Decimal Places | G10: Shell Colour | H10: Read and write | I10: Read and write
B11: Flatness Check Lower Limit | C11: %MD52 | D11: Real | E11: 3 Decimal Places
B12: Hub To Outer Door Offset | C12: %MD56 | D12: Real | E12: 3 Decimal Places
B13: Hub Height Upper Limit | C13: %MD60 | D13: Real | E13: 3 Decimal Places
B14: Hub Height Lower Limit | C14: %MD64 | D14: Real | E14: 3 Decimal Places
B15: Y-Axis Standby Position | C15: %DB299.DBD0 | D15: Real
B16: Y-Axis Bush Check Position | C16: %DB299.DBD4 | D16: Real
B17: Y-Axis Press Position | C17: %DB299.DBD8 | D17: Real
B18: Y-Axis Door Check Pos | C18: %DB299.DBD12 | D18: Real
B19: Y-Axis Pick and Place Robot Position | C19: %DB299.DBD16 | D19: Real
B20: Y-Axis Flatness Point #1 Position | C20: %DB2508.DBD0 | D20: Real
B21: Y-Axis Flatness Point #2 Position | C21: %DB2508.DBD4 | D21: Real
B22: Y-Axis Flatness Point #3 Position | C22: %DB2508.DBD8 | D22: Real
B23: Y-Axis Flatness Point #4 Position | C23: %DB2508.DBD12 | D23: Real
B24: Y-Axis Flatness Point #5 Position | C24: %DB2508.DBD16 | D24: Real
B25: Y-Axis Flatness Point #6 Position | C25: %DB2508.DBD20 | D25: Real
B26: Y-Axis Flatness Point #7 Position | C26: %DB2508.DBD24 | D26: Real
... B60: X-Axis Flatness Point #20 Position | C60: %DB2509.DBD76 | D60: Real

Sheet CAMLine
C3: Tag Name | D3: Data Type | E3: Address | F3: Send Command
C4: Trigger_HMI_Send_Start_Job | D4: Bool | E4: MR49603 | F4: START_JOB|BATCHID:<batch_id>|SERIAL_NO:<S/N>|EQID:<EQP ID>
C5: Lot ID | D5: String[50] | E5: EM1501 | F5: Batch_ID
C6: Foup_Barcode | D6: String[20] | E6: EM3050 | F6: S/N
C7: Equipment_ID | D7: String[26] | E7: EM3070 | F7: EQP_ID
C8: Start_Job_OK | D8: Bool | E8: MR49604 | F8: string 'OK'
C9: Start_Job_NOK | D9: Bool | E9: MR49605 | F9: other message that is not the string 'OK'.
C10: Trigger_HMI_Send_Job_Complete | D10: Bool | E10: MR49606 | F10: COMPLETED|BATCHID:<batch_id>|SERIAL_NO:<S/N>|EQID:<EQP ID>|RESULT:<PASS/FAIL>|VALUE:<PARAMETERNAME>,<MEASUREMENT VALUE>| Example: COMPLETED|BATCHID:M1M355969|SERIAL_NO:3873961|EQID:F-VEL 01|RESULT:PASS|VALUE:ST1,0.0083|VALUE:ST2,0.05|VALUE:ST3,0.001|VALUE:ST4,60.025|VALUE:ST5,0.0187|VALUE:ST6,0.05|VALUE:ST7,0.001|VALUE:ST8,0.001|VALUE:ST9,0.001
C11: Overall_Pass | D11: Bool | E11: MR49600 | F11: Result PASS
C12: Overall_Fail | D12: Bool | E12: MR49601 | F12: Result FAIL
C13: Screw Torque Reading | D13: Real | F13: <PARAMETERNAME>,<MEASUREMENT VALUE> Refer to the Example above. ST1 = Screw Torque 1
C14: Error_During_Testing | D14: Bool | E14: MR49607 | F14: ERR_MSG|ERR_MSG:<err_msg>|BATCHID:<batch_id>|SERIAL_NO:<S/N>|EQID:<EQP ID>
C19: Name | D19: DataType | E19: Address
C20: Screw Torque #1 | D20: Real | E20: EM3001
C21: Screw Torque #2 | D21: Real | E21: EM3003
C22: Screw Torque #3 | D22: Real | E22: EM3005
C23: Screw Torque #4 | D23: Real | E23: EM3007
C24: Screw Torque #5 | D24: Real | E24: EM3009
C25: Screw Torque #6 | D25: Real | E25: EM3011
C26: Screw Torque #7 | D26: Real | E26: EM3013
C27: Screw Torque #8 | D27: Real | E27: EM3015
C28: Screw Torque #9 | D28: Real | E28: EM3017
C29: Screw Torque #10 | D29: Real | E29: EM3019
C30: Screw Torque #11 | D30: Real | E30: EM3021
... C40: Screw Torque #21 | D40: Real | E40: EM3041

Sheet Motor Page (General
A1: Motor General
B2: PLC IP: | C2: 192.168.0.10
B3: NAME FOR PC: | C3: ='Main Page'!C3 -> HMI PC
B4: S7 Connection | C4: ='Main Page'!C4 -> Connection1
B6: Motor Tag Name | C6: Data Type | D6: offset | E6: Axis1
B7: Ready | C7: Bool | D7: 0 | E7: MR2001
B8: Stop | C8: Bool | D8: 0.1
B9: Axis_Error | C9: Bool | D9: 0.2 | E9: MR2007
B10: Reset | C10: Bool | D10: 0.3 | E10: MR403
B11: MotorAlarmBit | C11: Bool | D11: 0.4 | E11: R40002
B12: HomeDone | C12: Bool | D12: 0.5 | E12: MR2003
B13: Axis_HomingCommand | C13: Bool | D13: 0.6
B14: Axis_HomingDone | C14: Bool | D14: 0.7
B15: Axis_HomingInProg | C15: Bool | D15: 1
B16: Axis_Standstill | C16: Bool | D16: 1.1
B17: InPos | C17: Bool | D17: 1.2 | E17: R40001
B18: Axis_CurrentPosition | C18: DInt | D18: 2 | E18: EM4000
B19: ManualJog | C19: Bool | D19: 6 | E19: MR1003
B20: JogFwd | C20: Bool | D20: 6.1 | E20: MR2004
B21: JogFwd_Interlock | C21: Bool | D21: 6.2
B22: JogBwd | C22: Bool | D22: 6.3 | E22: MR2005
B23: JogBwd_Interlock | C23: Bool | D23: 6.4
B24: HomeReq | C24: Bool | D24: 6.5 | E24: MR2002
B25: HomeReq_Interlock | C25: Bool | D25: 6.6
B26: Homing | C26: Bool | D26: 6.7
B27: MoveAbs | C27: Bool | D27: 7
B28: MoveAbsInProgress | C28: Bool | D28: 7.1
B29: MoveAbs_Interlock | C29: Bool | D29: 7.2
B30: MoveRel | C30: Bool | D30: 7.3
B31: MoveRel_Interlock | C31: Bool | D31: 7.4
B32: MovePosition | C32: Real | D32: 8
B33: JogVelocity | C33: Real | D33: 12
B34: JogAcc | C34: Real | D34: 16
B35: JogDcc | C35: Real | D35: 20
B36: MoveVelocity | C36: Real | D36: 24
B37: MoveAcc | C37: Dint | D37: 28 | E37: EM4011
B38: MoveDcc | C38: Dint | D38: 32 | E38: EM4013
B39: Speed | C39: Dint | D39: 36 | E39: EM4009
B40: HMIStopAxis | C40: Bool | D40: 38
B41: HMIResetAxis | C41: Bool | D41: 38.1
...

Sheet Motor Page Position
A1: Motor Position
B2: PLC IP: | C2: 192.168.0.10
B3: NAME FOR PC: | C3: ='Main Page'!C3 -> HMI PC
B4: S7 Connection | C4: ='Main Page'!C4 -> Connection1
A6: Position
B7: Position Tag Name | C7: Data Type | D7: Offset | E7: Axis1
B8: Axis_Positions[0] | C8: DInt | E8: EM20000
B9: Axis_Positions[1] | C9: DInt | E9: EM20002
B10: Axis_Positions[2] | C10: DInt | E10: EM20004
A12: Toggle
B13: Motor Tag Name | C13: Data Type | D13: Offset | E13: Axis1
B14: HMI_Save_Current_Pos[0] | C14: Bool | E14: MR2100
B15: HMI_Save_Current_Pos[1] | C15: Bool | E15: MR2101
B16: HMI_Save_Current_Pos[2] | C16: Bool | E16: MR2102
B17: HMI_Save_Key-In_Pos[0] | C17: Bool | E17: MR2200
B18: HMI_Save_Key-In_Pos[1] | C18: Bool | E18: MR2201
B19: HMI_Save_Key-In_Pos[2] | C19: Bool | E19: MR2202
B20: HMI_Key-In_PosValue[0] | C20: DInt | E20: EM4030
B21: HMI_Key-In_PosValue[1] | C21: DInt | E21: EM4032
B22: HMI_Key-In_PosValue[2] | C22: DInt | E22: EM4034
B23: HMI_ManualGo[0] | C23: Bool | E23: MR2300
B24: HMI_ManualGo[1] | C24: Bool | E24: MR2301
B25: HMI_ManualGo[2] | C25: Bool | E25: MR2302
... B28: Axis_Position_Reached[2] | C28: Bool | E28: MR2402
A30: End

Sheet Foup Data
B2: For Display at Main Page
B3: 1. Display Name and Colour for each location
B6: Description | C6: Status No. | D6: Colour
B7: N/A | C7: 0 | D7: Grey
B8: Pass | C8: 1 | D8: Green
B9: Fail | C9: 2 | D9: Red
B13: Image No. | C13: Address | D13: Data Type | E13: R/W
B14: Inner Door | C14: %M280.5 | D14: Bool | E14: Read
B15: Outer Door | C15: %M280.6 | D15: Bool | E15: Read
B18: Inner Door
B19: No. | C19: Name | D19: Address | E19: DataType
B20: 0 | C20: Top_Wafer | D20: %DB460.DBW162 | E20: Int
B21: 2 | C21: Top_Cam#1 | D21: %DB460.DBW164 | E21: Int
B22: 9 | C22: Top_Cam#2 | D22: %DB460.DBW166 | E22: Int
B23: 3 | C23: Top_Hub#1 | D23: %DB460.DBW168 | E23: Int
B24: 3 | C24: Distance_Value[1] | D24: %DB460.DBD154 | E24: Real
B25: 10 | C25: Top_Hub#2 | D25: %DB460.DBW170 | E25: Int
B26: 10 | C26: Distance_Value[2] | D26: %DB460.DBD158 | E26: Real
B27: 5 | C27: Top_CamSpring#1 | D27: %DB460.DBW172 | E27: Int
B28: 28 | C28: Top_CamSpring#2 | D28: %DB460.DBW174 | E28: Int
B29: 1 | C29: Top_LatchArm#1 | D29: %DB460.DBW176 | E29: Int
B30: 4 | C30: Top_LatchArm#2 | D30: %DB460.DBW178 | E30: Int
B31: 7 | C31: Top_LatchArm#3 | D31: %DB460.DBW180 | E31: Int
... B48: 23 | C48: Side_Wafer_Node[7] | D48: %DB460.DBW226 | E48: Int
B49: 24 | C49: Side_Wafer_Node[4] | D49: %DB460.DBW220 | E49: Int | F49: *v1.0.5.1 change address and name
B50: 25 | C50: Side_Wafer_Node[3] | D50: %DB460.DBW218 | E50: Int | F50: *v1.0.5.1 change address and name
B51: 26 | C51: Side_Wafer_Node[2] | D51: %DB460.DBW216 | E51: Int | F51: *v1.0.5.1 change address and name
B52: 27 | C52: Side_Wafer_Node[1] | D52: %DB460.DBW214 | E52: Int | F52: *v1.0.5.1 change address and name
B53: 19 | C53: Number Code#1 | D53: %DB460.DBW240 | E53: Int | F53: *V1.0.5.1 Change address to bool
B54: 19 | C54: Number Code#2 | D54: P#DB460.DBX44.0 | E54: String[20] | F54: *v1.0.5.1 Remove Tag
B55: 29 | C55: Top_Extra_Part | D55: %DB460.DBW238 | E55: Int | F55: *v1.0.5.1 Add new tag
B56: 30 | C56: Inner_Door_Orientation | D56: %DB460.DBW302 | E56: Int | F56: *v1.0.5.1 Add new tag
B68: Outer Door
B70: No. | C70: Name | D70: Address | E70: DataType
B71: 1 | D71: %DB460.DBW184 | E71: Int
B72: 6 | C72: Top_Colour | D72: %DB460.DBW186 | E72: Int
B73: 6 | C73: Top_Gap | D73: %DB460.DBW190 | E73: Int
B74: 5 | C74: Barcode | D74: P#DB460.DBX0.0 | E74: String[20]
B75: 6 | C75: Number Code#1 | D75: P#DB460.DBX22.0 | E75: String[20]
B76: 6 | C76: Number Code#2 | D76: P#DB460.DBX44.0 | E76: String[20]
...

Sheet CSV File
B2: Folder/File naming | C2: Log folder name/Lot ID/Barcode_YYYYMMDD_HHMMSS.csv
B4: Tag Name | C4: Data Type | D4: Address
B5: Log_Foup_Data_Bit | C5: Bool | D5: %M280.3
B7: Tag Name | C7: Data Type | D7: Address
B8: Lot ID | C8: String | D8: P#DB850.DBX2.0
B9: Barcode | C9: String[20] | D9: P#DB460.DBX0.0
B12: No | C12: Number Code | E12: Flatness Value | G12: Hub Height | I12: Latch | K12: Corner | M12: Wafer Retainer Nodes | O12: Cam | Q12: Cam Spring | S12: Latch Arm | U12: Arrow | W12: Colour | Y12: Gap | AA12: Hub | AC12: Wafer Retainer
C13: Address | D13: Data Type | E13: Address | F13: Data Type | G13: Address | H13: Data Type | I13: Address | J13: Data Type | K13: Address | L13: Data Type | M13: Address | N13: Data Type | O13: Address | P13: Data Type | Q13: Address | R13: Data Type | S13: Address | T13: Data Type | U13: Address | V13: Data Type | W13: Address | X13: Data Type | Y13: Address | Z13: Data Type | AA13: Address | AB13: Data Type | AC13: Address | AD13: Data Type
B14: 1 | C14: P#DB460.DBX22.0 | D14: String[20] | E14: %DB460.DBD70 | F14: Real | G14: %DB460.DBD154 | H14: Real | I14: %DB460.DBW194 | J14: Int | K14: %DB460.DBW204 | L14: Int | M14: %DB460.DBW214 | N14: Int | O14: %DB460.DBW164 | P14: Int | Q14: %DB460.DBW172 | R14: Int | S14: %DB460.DBW176 | T14: Int | U14: %DB460.DBW184 | V14: Int | W14: %DB460.DBW186 | X14: Int | Y14: %DB460.DBW190 | Z14: Int | AA14: %DB460.DBW168 | AB14: Int | AC14: %DB460.DBW162 | AD14: Int
B15: 2 | C15: P#DB460.DBX44.0 | D15: String[20] | E15: %DB460.DBD74 | F15: Real | G15: %DB460.DBD158 | H15: Real | I15: %DB460.DBW196 | J15: Int | K15: %DB460.DBW206 | L15: Int | M15: %DB460.DBW216 | N15: Int | O15: %DB460.DBW166 | P15: Int | Q15: %DB460.DBW174 | R15: Int | S15: %DB460.DBW178 | T15: Int | AA15: %DB460.DBW170 | AB15: Int
B16: 3 | E16: %DB460.DBD78 | F16: Real | I16: %DB460.DBW198 | J16: Int | K16: %DB460.DBW208 | L16: Int | M16: %DB460.DBW218 | N16: Int | S16: %DB460.DBW180 | T16: Int
B17: 4 | E17: %DB460.DBD82 | F17: Real | I17: %DB460.DBW200 | J17: Int | K17: %DB460.DBW210 | L17: Int | M17: %DB460.DBW220 | N17: Int | S17: %DB460.DBW182 | T17: Int
B18: 5 | E18: %DB460.DBD86 | F18: Real | M18: %DB460.DBW222 | N18: Int
B19: 6 | E19: %DB460.DBD90 | F19: Real | M19: %DB460.DBW224 | N19: Int
B20: 7 | E20: %DB460.DBD94 | F20: Real | M20: %DB460.DBW226 | N20: Int
B21: 8 | E21: %DB460.DBD98 | F21: Real | M21: %DB460.DBW228 | N21: Int
B22: 9 | E22: %DB460.DBD102 | F22: Real
B23: 10 | E23: %DB460.DBD106 | F23: Real
B24: 11 | E24: %DB460.DBD110 | F24: Real
B25: 12 | E25: %DB460.DBD114 | F25: Real
B26: 13 | E26: %DB460.DBD118 | F26: Real
B27: 14 | E27: %DB460.DBD122 | F27: Real
B28: 15 | E28: %DB460.DBD126 | F28: Real
B29: 16 | E29: %DB460.DBD130 | F29: Real
B30: 17 | E30: %DB460.DBD134 | F30: Real
B31: 18 | E31: %DB460.DBD138 | F31: Real
B32: 19 | E32: %DB460.DBD142 | F32: Real
B33: 20 | E33: %DB460.DBD146 | F33: Real

Sheet Product Image
